Traceback (most recent call last):
  File "/root/AI_AgenBot/venv/lib/python3.12/site-packages/httpx/_transports/default.py", line 101, in map_httpcore_exceptions
    yield
  File "/root/AI_AgenBot/venv/lib/python3.12/site-packages/httpx/_transports/default.py", line 271, in __aiter__
    async for part in self._httpcore_stream:
  File "/root/AI_AgenBot/venv/lib/python3.12/site-packages/httpcore/_async/connection_pool.py", line 407, in __aiter__
    raise exc from None
  File "/root/AI_AgenBot/venv/lib/python3.12/site-packages/httpcore/_async/connection_pool.py", line 403, in __aiter__
    async for part in self._stream:
  File "/root/AI_AgenBot/venv/lib/python3.12/site-packages/httpcore/_async/http11.py", line 342, in __aiter__
    raise exc
  File "/root/AI_AgenBot/venv/lib/python3.12/site-packages/httpcore/_async/http11.py", line 334, in __aiter__
    async for chunk in self._connection._receive_response_body(**kwargs):
  File "/root/AI_AgenBot/venv/lib/python3.12/site-packages/httpcore/_async/http11.py", line 203, in _receive_response_body
    event = await self._receive_event(timeout=timeout)
            ^^^^^^^^^^^^^^^^^^^^^^^^^^^^^^^^^^^^^^^^^^
  File "/root/AI_AgenBot/venv/lib/python3.12/site-packages/httpcore/_async/http11.py", line 217, in _receive_event
    data = await self._network_stream.read(
           ^^^^^^^^^^^^^^^^^^^^^^^^^^^^^^^^
  File "/root/AI_AgenBot/venv/lib/python3.12/site-packages/httpcore/_backends/anyio.py", line 32, in read
    with map_exceptions(exc_map):
  File "/usr/lib/python3.12/contextlib.py", line 158, in __exit__
    self.gen.throw(value)
  File "/root/AI_AgenBot/venv/lib/python3.12/site-packages/httpcore/_exceptions.py", line 14, in map_exceptions
    raise to_exc(exc) from exc
httpcore.ReadError

The above exception was the direct cause of the following exception:

Traceback (most recent call last):
  File "/root/AI_AgenBot/venv/lib/python3.12/site-packages/telegram/ext/_application.py", line 1264, in process_update
    await coroutine
  File "/root/AI_AgenBot/venv/lib/python3.12/site-packages/telegram/ext/_handlers/basehandler.py", line 157, in handle_update
    return await self.callback(update, context)
           ^^^^^^^^^^^^^^^^^^^^^^^^^^^^^^^^^^^^
  File "/root/AI_AgenBot/handlers/message_handlers.py", line 20, in handle_all_messages
    response_text = await gemini_service.generate_text_response(user_id, text)
                    ^^^^^^^^^^^^^^^^^^^^^^^^^^^^^^^^^^^^^^^^^^^^^^^^^^^^^^^^^^
  File "/root/AI_AgenBot/services/gemini_service.py", line 108, in generate_text_response
    await e.response.aread()
  File "/root/AI_AgenBot/venv/lib/python3.12/site-packages/httpx/_models.py", line 979, in aread
    self._content = b"".join([part async for part in self.aiter_bytes()])
                             ^^^^^^^^^^^^^^^^^^^^^^^^^^^^^^^^^^^^^^^^^^^
  File "/root/AI_AgenBot/venv/lib/python3.12/site-packages/httpx/_models.py", line 997, in aiter_bytes
    async for raw_bytes in self.aiter_raw():
  File "/root/AI_AgenBot/venv/lib/python3.12/site-packages/httpx/_models.py", line 1055, in aiter_raw
    async for raw_stream_bytes in self.stream:
  File "/root/AI_AgenBot/venv/lib/python3.12/site-packages/httpx/_client.py", line 176, in __aiter__
    async for chunk in self._stream:
  File "/root/AI_AgenBot/venv/lib/python3.12/site-packages/httpx/_transports/default.py", line 270, in __aiter__
    with map_httpcore_exceptions():
  File "/usr/lib/python3.12/contextlib.py", line 158, in __exit__
    self.gen.throw(value)
  File "/root/AI_AgenBot/venv/lib/python3.12/site-packages/httpx/_transports/default.py", line 118, in map_httpcore_exceptions
    raise mapped_exc(message) from exc
httpx.ReadError